Workbook
Name PESO: #REF!

Sheet BD
A1: COLABORADORES | C1: PRODUTOS | D1: PROD. HORA | F1: MAQUINAS
A2: TIAGO | C2: GRAMPO 160 (CORTE) | D2: 550 | F2: FORJA 1
A3: SANDRO | C3: GRAMPO 160 (FORJA) | D3: 180 | F3: FORJA 2
A4: VINICIUS | C4: GRAMPO 160 (REBARBA) | D4: 284 | F4: FORJA 3
A5: JOÃO EDUARDO | C5: GRAMPO 160 (USINAGEM) | D5: 176 | F5: FORJA 4
A6: DANIEL | C6: GRAMPO 160 (SOLDA) | D6: 189 | F6: CNC 1
A7: CLAUDINEI | C7: SPADE 160 (CORTE) | D7: 340 | F7: CNC 2
A8: JOAO LOPES | C8: SPADE 160 (FORJA) | D8: 180 | F8: CNC 3
A9: EDMAR | C9: SPADE 160 (REBARBA) | D9: 284 | F9: CNC 4
A10: VAGNER | C10: SPADE 160 (USINAGEM) | D10: 112 | F10: CNC 5
A11: RENATO | C11: SPADE 160 (SOLDA) | D11: 171 | F11: SOLDA 1
A12: LEANDRO | C12: GRAMPO 400 (CORTE) | D12: 460 | F12: SOLDA 2
A13: VALMIR | C13: GRAMPO 400 (FORJA) | D13: 180 | F13: PH 1
A14: REGINALDO | C14: GRAMPO 400 (REBARBA) | F14: PH 2
A15: DHIEGO | C15: GRAMPO 400 (USINAGEM) | D15: 144 | F15: PP 80
A16: WILSON | C16: GRAMPO 400 (SOLDA) | D16: 133 | F16: PP 110
A17: ALEX | C17: SPADE 400 (CORTE) | D17: 200 | F17: SERRA 1
A18: PATRICIA | C18: SPADE 400 (FORJA) | D18: 180 | F18: TORNO
A19: RAFAEL | C19: SPADE 400 (REBARBA) | F19: LAMI. 1
A20: JOÃO BATISTA | C20: SPADE 400 (USINAGEM) | D20: 88 | F20: TORNO
A21: RAÍ | C21: SPADE 400 (SOLDA) | D21: 100 | F21: CENTRIFUGA
A22: MATEUS | C22: SPADE 800 (CORTE) | F22: -
A23: SANDRO | C23: SPADE 800 (FORJA) | D23: 60
A24: AGUINALDO | C24: SPADE 800 (REBARBA) | D24: 60
A25: ANDERSON | C25: SPADE 800 (USINAGEM) | D25: 32
A26: KILBER | C26: SPADE 800 (SOLDA) | D26: 39
A27: EDILSON | C27: HASTE 160 (CORTE) | D27: 39
A28: JOÃO PEDRO | C28: HASTE 160 (LAMINAÇÃO) | D28: 1000
A29: THIAGO ELIAS | C29: HASTE 400 (CORTE)
A30: FABIO | C30: HASTE 400 (LAMINAÇÃO) | D30: 800
C31: HASTE 800 (CORTE) | D31: 32
C32: HASTE 800 (LAMINAÇÃO) | D32: 39
C33: PRESILHA L (CORTE) | D33: 800
C34: PRESILHA INFERIOR (CORTE) | D34: 1160
C35: P. CABO AT (CORTE)
C36: P. CABO AT (REBAIXO) | D36: 350
C37: P. CABO AT (FORJA) | D37: 180
C38: P. CABO AT (REBARBA)
C39: P. CABO AT (FURO) | D39: 270
C40: P. CABO AT (LAMINAÇÃO) | D40: 900
...

Sheet BD_LANÇAMENTOS
A1: DATA : 25/05/2026 +B1+A1:J11+A1:K11+A1:T11+A1:J11 | B1: PRODUTIVIDADE POR MAQUINAS (TURNO ´´B``)
A2: MAQUINA | B2: PRODUTO | C2: OPERADOR | D2: QTD PRODUZIDA | E2: HORA INÍCIO | F2: HORA FIM | G2: HORAS PARADAS | H2: HORAS TRABALHADAS | I2: CAP. PRODUÇÃO (Hrs trabalhadas) | J2: PRODUT. % | K2: TOTAL HORA | L2: HORA/DIA | M2: MÊS | N2: DATA | O2: OPERAÇÃO | P2: MOTIVO PARADA | Q2: HORAS "ÚTEIS" | R2: HORAS NO DIA | S2: HORA/DIA2 | T2: CAP. PRODUÇÃO (Turno completo) | U2: PRODUT. %2
A3: SERRA 1 | B3: TERMINAL AT (CORTE) | C3: SANDRO | D3: 2926 | E3: 46166.875 | F3: 46167.25 | G3: 0.088194444 | H3: =(F3-E3)-G3 -> 0.28680556 | I3: =_xlfn.XLOOKUP(B3,[1]BD!C:C,[1]BD!D:D)*L3 -> 4405.3333 | J3: =IFERROR(D3/I3,"") -> 0.66419492 | K3: =H3*24*60 -> 413 | L3: =K3/60 -> 6.8833333 | M3: =IF([1]!Tabela5[[#This Row],[MAQUINA]]="","",TEXT([1]!Tabela5[[#This Row],[HORA INÍCIO]],"MMMM")) -> #REF! | N3: =IF([1]!Tabela5[[#This Row],[MAQUINA]]="","",DATE(YEAR(E3),MONTH(E3),DAY(E3))) -> #REF! | O3: =IFERROR(LEFT([1]!Tabela5[[#This Row],[MAQUINA]],SEARCH(" ",[1]!Tabela5[[#This Row],[MAQUINA]],1)-1),"") | Q3: =R3*24*60 -> 528 | R3: 0.36666667 | S3: 7.8 | T3: =_xlfn.XLOOKUP(B3,[1]BD!C:C,[1]BD!D:D)*S3 -> 4992 | U3: =IFERROR(D3/T3,"") -> 0.58613782
A4: FORJA 2 | B4: P. CABO AT (FORJA) | C4: JOÃO BATISTA | D4: 1337 | E4: 46166.875 | F4: 46167.25 | G4: 0.084722222 | H4: =(F4-E4)-G4 -> 0.29027778 | I4: =_xlfn.XLOOKUP(B4,[1]BD!C:C,[1]BD!D:D)*L4 -> 1254 | J4: =IFERROR(D4/I4,"") -> 1.0661882 | K4: =H4*24*60 -> 418 | L4: =K4/60 -> 6.9666667 | M4: =IF([1]!Tabela5[[#This Row],[MAQUINA]]="","",TEXT([1]!Tabela5[[#This Row],[HORA INÍCIO]],"MMMM")) -> #REF! | N4: =IF([1]!Tabela5[[#This Row],[MAQUINA]]="","",DATE(YEAR(E4),MONTH(E4),DAY(E4))) -> #REF! | O4: =IFERROR(LEFT([1]!Tabela5[[#This Row],[MAQUINA]],SEARCH(" ",[1]!Tabela5[[#This Row],[MAQUINA]],1)-1),"") | Q4: =R4*24*60 -> 528 | R4: 0.36666667 | S4: 7.8 | T4: =_xlfn.XLOOKUP(B4,[1]BD!C:C,[1]BD!D:D)*S4 -> 1404 | U4: =IFERROR(D4/T4,"") -> 0.9522792
A5: FORJA 3 | B5: TERMINAL AT (FORJA) | C5: REGINALDO | D5: 1150 | E5: 46166.875 | F5: 46167.25 | G5: 0.12361111 | H5: =(F5-E5)-G5 -> 0.25138889 | I5: =_xlfn.XLOOKUP(B5,[1]BD!C:C,[1]BD!D:D)*L5 -> 868.8 | J5: =IFERROR(D5/I5,"") -> 1.3236648 | K5: =H5*24*60 -> 362 | L5: =K5/60 -> 6.0333333 | M5: =IF([1]!Tabela5[[#This Row],[MAQUINA]]="","",TEXT([1]!Tabela5[[#This Row],[HORA INÍCIO]],"MMMM")) -> #REF! | N5: =IF([1]!Tabela5[[#This Row],[MAQUINA]]="","",DATE(YEAR(E5),MONTH(E5),DAY(E5))) -> #REF! | O5: =IFERROR(LEFT([1]!Tabela5[[#This Row],[MAQUINA]],SEARCH(" ",[1]!Tabela5[[#This Row],[MAQUINA]],1)-1),"") | Q5: =R5*24*60 -> 528 | R5: 0.36666667 | S5: 7.8 | T5: =_xlfn.XLOOKUP(B5,[1]BD!C:C,[1]BD!D:D)*S5 -> 1123.2 | U5: =IFERROR(D5/T5,"") -> 1.0238604
A6: SOLDA 1 | B6: GRAMPO 160 (SOLDA) | C6: VALMIR | D6: 780 | E6: 46166.875 | F6: 46167.25 | G6: 0.076388889 | H6: =(F6-E6)-G6 -> 0.29861111 | I6: =_xlfn.XLOOKUP(B6,[1]BD!C:C,[1]BD!D:D)*L6 -> 1354.5 | J6: =IFERROR(D6/I6,"") -> 0.57585825 | K6: =H6*24*60 -> 430 | L6: =K6/60 -> 7.1666667 | M6: =IF([1]!Tabela5[[#This Row],[MAQUINA]]="","",TEXT([1]!Tabela5[[#This Row],[HORA INÍCIO]],"MMMM")) -> #REF! | N6: =IF([1]!Tabela5[[#This Row],[MAQUINA]]="","",DATE(YEAR(E6),MONTH(E6),DAY(E6))) -> #REF! | O6: =IFERROR(LEFT([1]!Tabela5[[#This Row],[MAQUINA]],SEARCH(" ",[1]!Tabela5[[#This Row],[MAQUINA]],1)-1),"") | Q6: =R6*24*60 -> 528 | R6: 0.36666667 | S6: 7.8 | T6: =_xlfn.XLOOKUP(B6,[1]BD!C:C,[1]BD!D:D)*S6 -> 1474.2 | U6: =IFERROR(D6/T6,"") -> 0.52910053
A7: SOLDA 2 | B7: SPADE 160 (SOLDA) | C7: VINICIUS | D7: 695 | E7: 46166.875 | F7: 46167.25 | G7: 0.076388889 | H7: =(F7-E7)-G7 -> 0.29861111 | I7: =_xlfn.XLOOKUP(B7,[1]BD!C:C,[1]BD!D:D)*L7 -> 1225.5 | J7: =IFERROR(D7/I7,"") -> 0.56711546 | K7: =H7*24*60 -> 430 | L7: =K7/60 -> 7.1666667 | M7: =IF([1]!Tabela5[[#This Row],[MAQUINA]]="","",TEXT([1]!Tabela5[[#This Row],[HORA INÍCIO]],"MMMM")) -> #REF! | N7: =IF([1]!Tabela5[[#This Row],[MAQUINA]]="","",DATE(YEAR(E7),MONTH(E7),DAY(E7))) -> #REF! | O7: =IFERROR(LEFT([1]!Tabela5[[#This Row],[MAQUINA]],SEARCH(" ",[1]!Tabela5[[#This Row],[MAQUINA]],1)-1),"") | Q7: =R7*24*60 -> 528 | R7: 0.36666667 | S7: 7.8 | T7: =_xlfn.XLOOKUP(B7,[1]BD!C:C,[1]BD!D:D)*S7 -> 1333.8 | U7: =IFERROR(D7/T7,"") -> 0.52106763
A8: CNC 1 | B8: P. CABO AT (FURO) | C8: EDMAR | D8: 1648 | E8: 46166.875 | F8: 46167.25 | G8: 0.096527778 | H8: =(F8-E8)-G8 -> 0.27847222 | I8: =_xlfn.XLOOKUP(B8,[1]BD!C:C,[1]BD!D:D)*L8 -> 1804.5 | J8: =IFERROR(D8/I8,"") -> 0.91327237 | K8: =H8*24*60 -> 401 | L8: =K8/60 -> 6.6833333 | M8: =IF([1]!Tabela5[[#This Row],[MAQUINA]]="","",TEXT([1]!Tabela5[[#This Row],[HORA INÍCIO]],"MMMM")) -> #REF! | N8: =IF([1]!Tabela5[[#This Row],[MAQUINA]]="","",DATE(YEAR(E8),MONTH(E8),DAY(E8))) -> #REF! | O8: =IFERROR(LEFT([1]!Tabela5[[#This Row],[MAQUINA]],SEARCH(" ",[1]!Tabela5[[#This Row],[MAQUINA]],1)-1),"") | Q8: =R8*24*60 -> 528 | R8: 0.36666667 | S8: 7.8 | T8: =_xlfn.XLOOKUP(B8,[1]BD!C:C,[1]BD!D:D)*S8 -> 2106 | U8: =IFERROR(D8/T8,"") -> 0.78252612
A9: CNC 2 | B9: SPADE 160 (USINAGEM) | C9: JOÃO EDUARDO | D9: 920 | E9: 46166.875 | F9: 46167.25 | G9: 0.08125 | H9: =(F9-E9)-G9 -> 0.29375 | I9: =_xlfn.XLOOKUP(B9,[1]BD!C:C,[1]BD!D:D)*L9 -> 789.6 | J9: =IFERROR(D9/I9,"") -> 1.1651469 | K9: =H9*24*60 -> 423 | L9: =K9/60 -> 7.05 | M9: =IF([1]!Tabela5[[#This Row],[MAQUINA]]="","",TEXT([1]!Tabela5[[#This Row],[HORA INÍCIO]],"MMMM")) -> #REF! | N9: =IF([1]!Tabela5[[#This Row],[MAQUINA]]="","",DATE(YEAR(E9),MONTH(E9),DAY(E9))) -> #REF! | O9: =IFERROR(LEFT([1]!Tabela5[[#This Row],[MAQUINA]],SEARCH(" ",[1]!Tabela5[[#This Row],[MAQUINA]],1)-1),"") | Q9: =R9*24*60 -> 528 | R9: 0.36666667 | S9: 7.8 | T9: =_xlfn.XLOOKUP(B9,[1]BD!C:C,[1]BD!D:D)*S9 -> 873.6 | U9: =IFERROR(D9/T9,"") -> 1.0531136
A10: CNC 5 | B10: SPADE 400 (USINAGEM) | C10: MATEUS | D10: 696 | E10: 46166.875 | F10: 46167.25 | G10: 0.077083333 | H10: =(F10-E10)-G10 -> 0.29791667 | I10: =_xlfn.XLOOKUP(B10,[1]BD!C:C,[1]BD!D:D)*L10 -> 629.2 | J10: =IFERROR(D10/I10,"") -> 1.1061666 | K10: =H10*24*60 -> 429 | L10: =K10/60 -> 7.15 | M10: =IF([1]!Tabela5[[#This Row],[MAQUINA]]="","",TEXT([1]!Tabela5[[#This Row],[HORA INÍCIO]],"MMMM")) -> #REF! | N10: =IF([1]!Tabela5[[#This Row],[MAQUINA]]="","",DATE(YEAR(E10),MONTH(E10),DAY(E10))) -> #REF! | O10: =IFERROR(LEFT([1]!Tabela5[[#This Row],[MAQUINA]],SEARCH(" ",[1]!Tabela5[[#This Row],[MAQUINA]],1)-1),"") | Q10: =R10*24*60 -> 528 | R10: 0.36666667 | S10: 7.8 | T10: =_xlfn.XLOOKUP(B10,[1]BD!C:C,[1]BD!D:D)*S10 -> 686.4 | U10: =IFERROR(D10/T10,"") -> 1.013986
H11: =(F11-E11)-G11 -> 0 | I11: =_xlfn.XLOOKUP(B11,[1]BD!C:C,[1]BD!D:D)*L11 -> 0 | J11: =IFERROR(D11/I11,"") | K11: =H11*24*60 -> 0 | L11: =K11/60 -> 0 | M11: =IF([1]!Tabela5[[#This Row],[MAQUINA]]="","",TEXT([1]!Tabela5[[#This Row],[HORA INÍCIO]],"MMMM")) -> #REF! | N11: =IF([1]!Tabela5[[#This Row],[MAQUINA]]="","",DATE(YEAR(E11),MONTH(E11),DAY(E11))) -> #REF! | O11: =IFERROR(LEFT([1]!Tabela5[[#This Row],[MAQUINA]],SEARCH(" ",[1]!Tabela5[[#This Row],[MAQUINA]],1)-1),"") | Q11: =R11*24*60 -> 0 | S11: =Q11/60 -> 0 | T11: =_xlfn.XLOOKUP(B11,[1]BD!C:C,[1]BD!D:D)*S11 -> 0 | U11: =IFERROR(D11/T11,"")
A12: PH 1 | B12: GRAMPO 160 (REBARBA) | C12: JOAO LOPES | D12: 96 | E12: 46167.25 | F12: 46167.292 | G12: 0.027777778 | H12: =(F12-E12)-G12 -> 0.013888889 | I12: =_xlfn.XLOOKUP(B12,[1]BD!C:C,[1]BD!D:D)*L12 -> 94.666667 | J12: =IFERROR(D12/I12,"") -> 1.0140845 | K12: =H12*24*60 -> 20 | L12: =K12/60 -> 0.33333333 | M12: =IF([1]!Tabela5[[#This Row],[MAQUINA]]="","",TEXT([1]!Tabela5[[#This Row],[HORA INÍCIO]],"MMMM")) -> #REF! | N12: =IF([1]!Tabela5[[#This Row],[MAQUINA]]="","",DATE(YEAR(E12),MONTH(E12),DAY(E12))) -> #REF! | O12: =IFERROR(LEFT([1]!Tabela5[[#This Row],[MAQUINA]],SEARCH(" ",[1]!Tabela5[[#This Row],[MAQUINA]],1)-1),"") | Q12: =R12*24*60 -> 528 | R12: 0.36666667 | S12: =Q12/60 -> 8.8 | T12: =_xlfn.XLOOKUP(B12,[1]BD!C:C,[1]BD!D:D)*S12 -> 2499.2 | U12: =IFERROR(D12/T12,"") -> 0.038412292
A13: PH 1 | B13: GRAMPO 400 (REBARBA) | C13: JOAO LOPES | D13: 1183 | E13: 46167.292 | F13: 46167.588 | G13: 0.068055556 | H13: =(F13-E13)-G13 -> 0.22777778 | I13: =_xlfn.XLOOKUP(B13,[1]BD!C:C,[1]BD!D:D)*L13 -> 0 | J13: =IFERROR(D13/I13,"") | K13: =H13*24*60 -> 328 | L13: =K13/60 -> 5.4666667 | M13: =IF([1]!Tabela5[[#This Row],[MAQUINA]]="","",TEXT([1]!Tabela5[[#This Row],[HORA INÍCIO]],"MMMM")) -> #REF! | N13: =IF([1]!Tabela5[[#This Row],[MAQUINA]]="","",DATE(YEAR(E13),MONTH(E13),DAY(E13))) -> #REF! | O13: =IFERROR(LEFT([1]!Tabela5[[#This Row],[MAQUINA]],SEARCH(" ",[1]!Tabela5[[#This Row],[MAQUINA]],1)-1),"") | Q13: =R13*24*60 -> 528 | R13: 0.36666667 | S13: =Q13/60 -> 8.8 | T13: =_xlfn.XLOOKUP(B13,[1]BD!C:C,[1]BD!D:D)*S13 -> 0 | U13: =IFERROR(D13/T13,"")
A14: PH 1 | B14: GRAMPO 400 (REBARBA) | C14: FABIO | D14: 300 | E14: 46167.588 | F14: 46167.667 | G14: 0.010416667 | H14: =(F14-E14)-G14 -> 0.06875 | I14: =_xlfn.XLOOKUP(B14,[1]BD!C:C,[1]BD!D:D)*L14 -> 0 | J14: =IFERROR(D14/I14,"") | K14: =H14*24*60 -> 99 | L14: =K14/60 -> 1.65 | M14: =IF([1]!Tabela5[[#This Row],[MAQUINA]]="","",TEXT([1]!Tabela5[[#This Row],[HORA INÍCIO]],"MMMM")) -> #REF! | N14: =IF([1]!Tabela5[[#This Row],[MAQUINA]]="","",DATE(YEAR(E14),MONTH(E14),DAY(E14))) -> #REF! | O14: =IFERROR(LEFT([1]!Tabela5[[#This Row],[MAQUINA]],SEARCH(" ",[1]!Tabela5[[#This Row],[MAQUINA]],1)-1),"") | Q14: =R14*24*60 -> 528 | R14: 0.36666667 | S14: =Q14/60 -> 8.8 | T14: =_xlfn.XLOOKUP(B14,[1]BD!C:C,[1]BD!D:D)*S14 -> 0 | U14: =IFERROR(D14/T14,"")
A15: PH 2 | B15: SPADE 400 (REBARBA) | C15: DANIEL | D15: 1845 | E15: 46167.25 | F15: 46167.667 | G15: 0.11041667 | H15: =(F15-E15)-G15 -> 0.30625 | I15: =_xlfn.XLOOKUP(B15,[1]BD!C:C,[1]BD!D:D)*L15 -> 0 | J15: =IFERROR(D15/I15,"") | K15: =H15*24*60 -> 441 | L15: =K15/60 -> 7.35 | M15: =IF([1]!Tabela5[[#This Row],[MAQUINA]]="","",TEXT([1]!Tabela5[[#This Row],[HORA INÍCIO]],"MMMM")) -> #REF! | N15: =IF([1]!Tabela5[[#This Row],[MAQUINA]]="","",DATE(YEAR(E15),MONTH(E15),DAY(E15))) -> #REF! | O15: =IFERROR(LEFT([1]!Tabela5[[#This Row],[MAQUINA]],SEARCH(" ",[1]!Tabela5[[#This Row],[MAQUINA]],1)-1),"") | Q15: =R15*24*60 -> 528 | R15: 0.36666667 | S15: =Q15/60 -> 8.8 | T15: =_xlfn.XLOOKUP(B15,[1]BD!C:C,[1]BD!D:D)*S15 -> 0 | U15: =IFERROR(D15/T15,"")
A16: FORJA 1 | B16: GRAMPO 400 (FORJA) | C16: ANDERSON | D16: 604 | E16: 46167.25 | F16: 46167.451 | G16: 0.022222222 | H16: =(F16-E16)-G16 -> 0.17916667 | I16: =_xlfn.XLOOKUP(B16,[1]BD!C:C,[1]BD!D:D)*L16 -> 774 | J16: =IFERROR(D16/I16,"") -> 0.78036176 | K16: =H16*24*60 -> 258 | L16: =K16/60 -> 4.3 | M16: =IF([1]!Tabela5[[#This Row],[MAQUINA]]="","",TEXT([1]!Tabela5[[#This Row],[HORA INÍCIO]],"MMMM")) -> #REF! | N16: =IF([1]!Tabela5[[#This Row],[MAQUINA]]="","",DATE(YEAR(E16),MONTH(E16),DAY(E16))) -> #REF! | O16: =IFERROR(LEFT([1]!Tabela5[[#This Row],[MAQUINA]],SEARCH(" ",[1]!Tabela5[[#This Row],[MAQUINA]],1)-1),"") | Q16: =R16*24*60 -> 528 | R16: 0.36666667 | S16: =Q16/60 -> 8.8 | T16: =_xlfn.XLOOKUP(B16,[1]BD!C:C,[1]BD!D:D)*S16 -> 1584 | U16: =IFERROR(D16/T16,"") -> 0.38131313
A17: FORJA 1 | B17: P. CABO BT 400 (FORJA) | C17: ANDERSON | D17: 109 | E17: 46167.451 | F17: 46167.667 | G17: 0.10069444 | H17: =(F17-E17)-G17 -> 0.11458333 | I17: =_xlfn.XLOOKUP(B17,[1]BD!C:C,[1]BD!D:D)*L17 -> 495 | J17: =IFERROR(D17/I17,"") -> 0.22020202 | K17: =H17*24*60 -> 165 | L17: =K17/60 -> 2.75 | M17: =IF([1]!Tabela5[[#This Row],[MAQUINA]]="","",TEXT([1]!Tabela5[[#This Row],[HORA INÍCIO]],"MMMM")) -> #REF! | N17: =IF([1]!Tabela5[[#This Row],[MAQUINA]]="","",DATE(YEAR(E17),MONTH(E17),DAY(E17))) -> #REF! | O17: =IFERROR(LEFT([1]!Tabela5[[#This Row],[MAQUINA]],SEARCH(" ",[1]!Tabela5[[#This Row],[MAQUINA]],1)-1),"") | Q17: =R17*24*60 -> 528 | R17: 0.36666667 | S17: =Q17/60 -> 8.8 | T17: =_xlfn.XLOOKUP(B17,[1]BD!C:C,[1]BD!D:D)*S17 -> 1584 | U17: =IFERROR(D17/T17,"") -> 0.068813131
A18: FORJA 2 | B18: P. CABO AT (FORJA) | C18: KILBER | D18: 1250 | E18: 46167.25 | F18: 46167.667 | G18: 0.066666667 | H18: =(F18-E18)-G18 -> 0.35 | I18: =_xlfn.XLOOKUP(B18,[1]BD!C:C,[1]BD!D:D)*L18 -> 1512 | J18: =IFERROR(D18/I18,"") -> 0.82671958 | K18: =H18*24*60 -> 504 | L18: =K18/60 -> 8.4 | M18: =IF([1]!Tabela5[[#This Row],[MAQUINA]]="","",TEXT([1]!Tabela5[[#This Row],[HORA INÍCIO]],"MMMM")) -> #REF! | N18: =IF([1]!Tabela5[[#This Row],[MAQUINA]]="","",DATE(YEAR(E18),MONTH(E18),DAY(E18))) -> #REF! | O18: =IFERROR(LEFT([1]!Tabela5[[#This Row],[MAQUINA]],SEARCH(" ",[1]!Tabela5[[#This Row],[MAQUINA]],1)-1),"") | Q18: =R18*24*60 -> 528 | R18: 0.36666667 | S18: =Q18/60 -> 8.8 | T18: =_xlfn.XLOOKUP(B18,[1]BD!C:C,[1]BD!D:D)*S18 -> 1584 | U18: =IFERROR(D18/T18,"") -> 0.78914141
A19: FORJA 3 | B19: TERMINAL AT (FORJA) | C19: AGUINALDO | D19: 2000 | E19: 46167.25 | F19: 46167.708 | G19: 0.077083333 | H19: =(F19-E19)-G19 -> 0.38125 | I19: =_xlfn.XLOOKUP(B19,[1]BD!C:C,[1]BD!D:D)*L19 -> 1317.6 | J19: =IFERROR(D19/I19,"") -> 1.5179114 | K19: =H19*24*60 -> 549 | L19: =K19/60 -> 9.15 | M19: =IF([1]!Tabela5[[#This Row],[MAQUINA]]="","",TEXT([1]!Tabela5[[#This Row],[HORA INÍCIO]],"MMMM")) -> #REF! | N19: =IF([1]!Tabela5[[#This Row],[MAQUINA]]="","",DATE(YEAR(E19),MONTH(E19),DAY(E19))) -> #REF! | O19: =IFERROR(LEFT([1]!Tabela5[[#This Row],[MAQUINA]],SEARCH(" ",[1]!Tabela5[[#This Row],[MAQUINA]],1)-1),"") | Q19: =R19*24*60 -> 528 | R19: 0.36666667 | S19: =Q19/60 -> 8.8 | T19: =_xlfn.XLOOKUP(B19,[1]BD!C:C,[1]BD!D:D)*S19 -> 1267.2 | U19: =IFERROR(D19/T19,"") -> 1.5782828
A20: SOLDA 1 | B20: SPADE 160 (SOLDA) | C20: CLAUDINEI | D20: 414 | E20: 46167.25 | F20: 46167.446 | G20: 0.051388889 | H20: =(F20-E20)-G20 -> 0.14444444 | I20: =_xlfn.XLOOKUP(B20,[1]BD!C:C,[1]BD!D:D)*L20 -> 592.8 | J20: =IFERROR(D20/I20,"") -> 0.69838057 | K20: =H20*24*60 -> 208 | L20: =K20/60 -> 3.4666667 | M20: =IF([1]!Tabela5[[#This Row],[MAQUINA]]="","",TEXT([1]!Tabela5[[#This Row],[HORA INÍCIO]],"MMMM")) -> #REF! | N20: =IF([1]!Tabela5[[#This Row],[MAQUINA]]="","",DATE(YEAR(E20),MONTH(E20),DAY(E20))) -> #REF! | O20: =IFERROR(LEFT([1]!Tabela5[[#This Row],[MAQUINA]],SEARCH(" ",[1]!Tabela5[[#This Row],[MAQUINA]],1)-1),"") | Q20: =R20*24*60 -> 528 | R20: 0.36666667 | S20: =Q20/60 -> 8.8 | T20: =_xlfn.XLOOKUP(B20,[1]BD!C:C,[1]BD!D:D)*S20 -> 1504.8 | U20: =IFERROR(D20/T20,"") -> 0.27511962
A21: SOLDA 1 | B21: SPADE 400 (SOLDA) | C21: CLAUDINEI | D21: 320 | E21: 46167.446 | F21: 46167.667 | G21: 0.055555556 | H21: =(F21-E21)-G21 -> 0.16527778 | I21: =_xlfn.XLOOKUP(B21,[1]BD!C:C,[1]BD!D:D)*L21 -> 396.66667 | J21: =IFERROR(D21/I21,"") -> 0.80672269 | K21: =H21*24*60 -> 238 | L21: =K21/60 -> 3.9666667 | M21: =IF([1]!Tabela5[[#This Row],[MAQUINA]]="","",TEXT([1]!Tabela5[[#This Row],[HORA INÍCIO]],"MMMM")) -> #REF! | N21: =IF([1]!Tabela5[[#This Row],[MAQUINA]]="","",DATE(YEAR(E21),MONTH(E21),DAY(E21))) -> #REF! | O21: =IFERROR(LEFT([1]!Tabela5[[#This Row],[MAQUINA]],SEARCH(" ",[1]!Tabela5[[#This Row],[MAQUINA]],1)-1),"") | Q21: =R21*24*60 -> 528 | R21: 0.36666667 | S21: =Q21/60 -> 8.8 | T21: =_xlfn.XLOOKUP(B21,[1]BD!C:C,[1]BD!D:D)*S21 -> 880 | U21: =IFERROR(D21/T21,"") -> 0.36363636
A22: SOLDA 2 | B22: SPADE 160 (SOLDA) | C22: RAFAEL | D22: 390 | E22: 46167.25 | F22: 46167.396 | G22: 0.041666667 | H22: =(F22-E22)-G22 -> 0.10416667 | I22: =_xlfn.XLOOKUP(B22,[1]BD!C:C,[1]BD!D:D)*L22 -> 427.5 | J22: =IFERROR(D22/I22,"") -> 0.9122807 | K22: =H22*24*60 -> 150 | L22: =K22/60 -> 2.5 | M22: =IF([1]!Tabela5[[#This Row],[MAQUINA]]="","",TEXT([1]!Tabela5[[#This Row],[HORA INÍCIO]],"MMMM")) -> #REF! | N22: =IF([1]!Tabela5[[#This Row],[MAQUINA]]="","",DATE(YEAR(E22),MONTH(E22),DAY(E22))) -> #REF! | O22: =IFERROR(LEFT([1]!Tabela5[[#This Row],[MAQUINA]],SEARCH(" ",[1]!Tabela5[[#This Row],[MAQUINA]],1)-1),"") | Q22: =R22*24*60 -> 528 | R22: 0.36666667 | S22: =Q22/60 -> 8.8 | T22: =_xlfn.XLOOKUP(B22,[1]BD!C:C,[1]BD!D:D)*S22 -> 1504.8 | U22: =IFERROR(D22/T22,"") -> 0.25917065
A23: SOLDA 2 | B23: SPADE 400 (SOLDA) | C23: RAFAEL | D23: 200 | E23: 46167.396 | F23: 46167.667 | G23: 0.14027778 | H23: =(F23-E23)-G23 -> 0.13055556 | I23: =_xlfn.XLOOKUP(B23,[1]BD!C:C,[1]BD!D:D)*L23 -> 313.33333 | J23: =IFERROR(D23/I23,"") -> 0.63829787 | K23: =H23*24*60 -> 188 | L23: =K23/60 -> 3.1333333 | M23: =IF([1]!Tabela5[[#This Row],[MAQUINA]]="","",TEXT([1]!Tabela5[[#This Row],[HORA INÍCIO]],"MMMM")) -> #REF! | N23: =IF([1]!Tabela5[[#This Row],[MAQUINA]]="","",DATE(YEAR(E23),MONTH(E23),DAY(E23))) -> #REF! | O23: =IFERROR(LEFT([1]!Tabela5[[#This Row],[MAQUINA]],SEARCH(" ",[1]!Tabela5[[#This Row],[MAQUINA]],1)-1),"") | Q23: =R23*24*60 -> 528 | R23: 0.36666667 | S23: =Q23/60 -> 8.8 | T23: =_xlfn.XLOOKUP(B23,[1]BD!C:C,[1]BD!D:D)*S23 -> 880 | U23: =IFERROR(D23/T23,"") -> 0.22727273
... A31: PP 80 | B31: P. CABO AT (REBARBA) | C31: RENATO | D31: 3658 | E31: 46167.25 | F31: 46167.667 | G31: 0.072916667 | H31: =(F31-E31)-G31 -> 0.34375 | I31: =_xlfn.XLOOKUP(B31,[1]BD!C:C,[1]BD!D:D)*L31 -> 0 | J31: =IFERROR(D31/I31,"") | K31: =H31*24*60 -> 495 | L31: =K31/60 -> 8.25 | M31: =IF([1]!Tabela5[[#This Row],[MAQUINA]]="","",TEXT([1]!Tabela5[[#This Row],[HORA INÍCIO]],"MMMM")) -> #REF! | N31: =IF([1]!Tabela5[[#This Row],[MAQUINA]]="","",DATE(YEAR(E31),MONTH(E31),DAY(E31))) -> #REF! | O31: =IFERROR(LEFT([1]!Tabela5[[#This Row],[MAQUINA]],SEARCH(" ",[1]!Tabela5[[#This Row],[MAQUINA]],1)-1),"") | Q31: =R31*24*60 -> 528 | R31: 0.36666667 | S31: =Q31/60 -> 8.8 | T31: =_xlfn.XLOOKUP(B31,[1]BD!C:C,[1]BD!D:D)*S31 -> 0 | U31: =IFERROR(D31/T31,"")
A33: MÁQUINAS | B33: PRODUTOS | D33: PEÇAS | F33: PESO KGS
A34: SOLDA 1 | B34: GRAMPO 160 (SOLDA) | D34: 780 | F34: 197.34
A35: SOLDA 2 | B35: SPADE 160 (SOLDA) | D35: 1499 | F35: 437.708
A36: SOLDA 2 | B36: SPADE 400 (SOLDA) | D36: 520 | F36: 444.08
A37: LAMI. 1 | B37: P. CABO AT (LAMINAÇÃO) | D37: 6455 | F37: 548.675
D40: =SUM(D34:E38) -> 9254 | F40: =SUM(F34:I38) -> 1627.803
A41: META DIA | D41: X | E41: REALIZADO | H41: %
A43: 1700 | E43: =F40 -> 1627.803 | H43: =E43/A43 -> 0.95753118
A50: PERCAS | C50: QTD | D50: PESO
A51: P. CABO AT (FORJA) | C51: 1 | D51: =C51*E51 -> 0.109 | E51: =_xlfn.XLOOKUP(A51,[2]BD!C:C,[2]BD!D:D) -> 0.109
A52: SPADE 400 (USINAGEM) | C52: 7 | D52: =C52*E52 -> 4.193 | E52: =_xlfn.XLOOKUP(A52,[2]BD!C:C,[2]BD!D:D) -> 0.599
A53: GRAMPO 400 (FORJA) | C53: 26 | D53: =C53*E53 -> 15.6 | E53: =_xlfn.XLOOKUP(A53,[2]BD!C:C,[2]BD!D:D) -> 0.6
A54: P. CABO BT 400 (FORJA) | C54: 52 | D54: =C54*E54 -> 17.004 | E54: =_xlfn.XLOOKUP(A54,[2]BD!C:C,[2]BD!D:D) -> 0.327
A55: P. CABO AT (FORJA) | C55: 29 | D55: =C55*E55 -> 3.161 | E55: =_xlfn.XLOOKUP(A55,[2]BD!C:C,[2]BD!D:D) -> 0.109
A56: SPADE 400 (SOLDA) | C56: 3 | D56: =C56*E56 -> 2.562 | E56: =_xlfn.XLOOKUP(A56,[2]BD!C:C,[2]BD!D:D) -> 0.854
A57: P. CABO AT (FURO) | C57: 50 | D57: =C57*E57 -> 4.15 | E57: =_xlfn.XLOOKUP(A57,[2]BD!C:C,[2]BD!D:D) -> 0.083
...

Sheet PRODUTO
A1: CÓDIGO: | B1: DESCRIÇÃO: | C1: PESO: | D1: CONSUMO MP [KG] | E1: STATUS
A2: 411 | C2: 0.16 | E2: ATIVO
A3: 412 | B3: ANEL DA FLANGE C/ FURO | C3: 0.15 | E3: ATIVO
A4: 413 | B4: ANEL DA FLANGE C/ FURO E ROSCA | C4: 0.15 | E4: ATIVO
A5: 414 | B5: ANEL DA FLANGE C/ FURO E ROSCA OXIDADO | C5: 0.15 | E5: ATIVO
A6: 2191 | B6: APARAS E PONTAS DE COBRE | C6: 1 | E6: ATIVO
A7: 2183 | B7: APARAS E PONTAS DE LATAO | C7: 1 | E7: ATIVO
A8: 2646 | B8: BLANK CHAPA CORTADA | C8: 1 | E8: ATIVO
A9: 405 | B9: BLANK DE CHAPA N/S 105MM E 146MM | E9: INATIVO
A10: 1434 | B10: BLANK DE CHAPA N/S 105MM E 146MM EM KG | E10: INATIVO
A11: 2207 | B11: BLANK HASTE AT | E11: INATIVO
A12: 2218 | B12: BLANK PINO CONDUTOR AT | C12: 0.12 | E12: ATIVO
A13: 702218 | B13: BLANK PINO CONDUTOR AT IMP | C13: 0.12 | E13: ATIVO
A14: 2205 | B14: BLANK PRENSA CABO AT | C14: 0.137 | E14: ATIVO
A15: 702205 | B15: BLANK PRENSA CABO AT IMP | C15: 0.137 | E15: ATIVO
A16: 2180 | B16: BLANK PRENSA CABO BT 160A | C16: 0.262 | E16: ATIVO
A17: 702180 | B17: BLANK PRENSA CABO BT 160A IMP | C17: 0.262 | E17: ATIVO
A18: 2494 | B18: BLANK PRENSA CABO BT 400A | C18: 0.47 | E18: ATIVO
A19: 702494 | B19: BLANK PRENSA CABO BT 400A IMP | C19: 0.47 | E19: ATIVO
A20: 2119 | B20: BLANK TERMINAL 160A SPADE | C20: 0.3 | E20: ATIVO
A21: 702119 | B21: BLANK TERMINAL 160A SPADE IMP | C21: 0.3 | E21: ATIVO
A22: 2177 | B22: BLANK TERMINAL 160A GRAMPO | C22: 0.268 | E22: ATIVO
A23: 702177 | B23: BLANK TERMINAL 160A GRAMPO IMP | C23: 0.268 | E23: ATIVO
... A51: 2182 | B51: CAVACO E PO DE LATAO | C51: 1 | E51: ATIVO
A52: 402 | B52: CONFECCAO DO GANCHO | E52: INATIVO
A53: 408 | B53: CONFECCAO PRESILHA | E53: INATIVO
A54: 661 | B54: CONFECCAO PRESILHA CHAPA NOVA | E54: INATIVO
A55: 538 | B55: CONFECCAO PRESILHA SUCATA | E55: INATIVO
A56: 1850 | B56: FIO 3CP COBRE 2,7 X 5,5MM | E56: INATIVO
A57: 832040 | B57: FIO ALUM. 3CP 2,0 X 4,0 NAC | C57: 1 | E57: ATIVO
A58: 932040 | B58: FIO ALUM. 3CP 2,0 X 4,0 IMP | C58: 1 | E58: ATIVO
A59: 832545 | B59: FIO ALUM. 3CP 2,5 X 4,5 NAC | C59: 1 | E59: ATIVO
A60: 932537 | B60: FIO ALUM. 3CP 2,5 X 3,7 IMP | C60: 1 | E60: ATIVO
A61: 832790 | B61: FIO ALUM. 3CP 2,7 X 9,0 NAC | C61: 1 | E61: ATIVO
A62: 932790 | B62: FIO ALUM. 3CP 2,7 X 9,0 IMP | C62: 1 | E62: ATIVO
A63: 833010 | B63: FIO ALUM. 3CP 3,0 X 10,0 NAC | C63: 1 | E63: ATIVO
A64: 833011 | B64: FIO ALUM. 3CP 3,0 X 11,3 NAC | C64: 1 | E64: ATIVO
A65: 833012 | B65: FIO ALUM. 3CP 3,0 X 12,0 NAC | C65: 1 | E65: ATIVO
A66: 833040 | B66: FIO ALUM. 3CP 3,0 X 4,0 NAC | C66: 1 | E66: ATIVO
A67: 833045 | B67: FIO ALUM. 3CP 3,0 X 4,5 NAC | C67: 1 | E67: ATIVO
...

Sheet META POR HORA
A1: DECRIÇÃO | B1: META DIA | C1: META HORA
A2: GRAMPO 160 (FORJA) | B2: 1584 | C2: 180
A3: GRAMPO 160 (USINAGEM) | B3: 1300
A4: GRAMPO 160 (SOLDA) | B4: 1650
A5: SPADE 160 (FORJA) | B5: 1584 | C5: 180
A6: SPADE 160 (USINAGEM) | B6: 1200
A7: SPADE 160 (SOLDA) | B7: 1300
A8: GRAMPO 400 (FORJA) | B8: 1000 | C8: 180
A9: GRAMPO 400 (USINAGEM) | B9: 844
A10: GRAMPO 400 (SOLDA) | B10: 700
A11: SPADE 400 (FORJA) | B11: 1584 | C11: 180
A12: SPADE 400 (USINAGEM) | B12: 900
A13: SPADE 400 (SOLDA) | B13: 800
A14: SPADE 800 (FORJA) | B14: 500 | C14: 60
A15: SPADE 800 (USINAGEM) | B15: 280
A16: SPADE 800 (SOLDA) | B16: 340
A17: P. CABO AT (REBAIXO) | B17: 2156 | C17: 245
A18: P. CABO AT (FORJA) | B18: 1584 | C18: 180
A19: P. CABO AT (FURO) | B19: 2432
A20: P. CABO BT 160 (REBAIXO) | B20: 2600
A21: P. CABO BT 160 (FORJA) | B21: 1584 | C21: 180
A22: P. CABO BT 160 (FURO) | B22: 2432
A23: P. CABO BT 400 (REBAIXO) | B23: 1584
A24: P. CABO BT 400 (FORJA) | C24: 180
A25: P. CABO BT 400 (FURO) | B25: 1000
A26: TERMINAL AT (FORJA) | B26: 1250 | C26: 144
A27: TERMINAL AT (USINAGEM) | B27: 950
A28: PINO CONDUTOR (REBAIXO) | B28: 2000
A29: PINO CONDUTOR (FORJA) | B29: 2500 | C29: 180

Sheet Planilha1
A3: Rótulos de Linha | B3: Soma de QTD PRODUZIDA
A4: EDMAR | B4: 1005
A5: SANDRO | B5: 1068
A6: CNC 4 | B6: 1068
A7: TERMINAL AT (USINAGEM) | B7: 1068
A8: REGINALDO | B8: 1400
A9: FORJA 1 | B9: 1400
A10: P. CABO AT (FORJA) | B10: 1400
A11: VINICIUS | B11: 840
A12: CNC 2 | B12: 840
A13: SPADE 160 (USINAGEM) | B13: 840
A14: VALMIR | B14: 930
A15: SOLDA 2 | B15: 930
... A23: Total Geral | B23: 7820

Sheet PROJETO
A2: PRODUÇÃO TERMINAIS | Y2: 46007
E3: PRODUÇÃO
A4: FORJA | B4: PRODUÇÃO | D4: Janeiro | E4: =SUMIFS(BD_LANÇAMENTOS!D:D,BD_LANÇAMENTOS!M:M,D4,BD_LANÇAMENTOS!O:O,$A$4) -> 0
A5: JOSÉ MARIO | B5: =SUMIFS(BD_LANÇAMENTOS!D:D,BD_LANÇAMENTOS!C:C,A5,BD_LANÇAMENTOS!N:N,PROJETO!$Y$2,BD_LANÇAMENTOS!O:O,$A$4) -> 0 | D5: Fevereiro | E5: =SUMIFS(BD_LANÇAMENTOS!D:D,BD_LANÇAMENTOS!M:M,D5,BD_LANÇAMENTOS!O:O,$A$4) -> 0
A6: JOÃO PAULO | B6: =SUMIFS(BD_LANÇAMENTOS!D:D,BD_LANÇAMENTOS!C:C,A6,BD_LANÇAMENTOS!N:N,PROJETO!$Y$2,BD_LANÇAMENTOS!O:O,$A$4) -> 0 | D6: Março | E6: =SUMIFS(BD_LANÇAMENTOS!D:D,BD_LANÇAMENTOS!M:M,D6,BD_LANÇAMENTOS!O:O,$A$4) -> 0
A7: RAFAEL | B7: =SUMIFS(BD_LANÇAMENTOS!D:D,BD_LANÇAMENTOS!C:C,A7,BD_LANÇAMENTOS!N:N,PROJETO!$Y$2,BD_LANÇAMENTOS!O:O,$A$4) -> 0 | D7: Abril | E7: =SUMIFS(BD_LANÇAMENTOS!D:D,BD_LANÇAMENTOS!M:M,D7,BD_LANÇAMENTOS!O:O,$A$4) -> 0
A8: JOÃO BATISTA | B8: =SUMIFS(BD_LANÇAMENTOS!D:D,BD_LANÇAMENTOS!C:C,A8,BD_LANÇAMENTOS!N:N,PROJETO!$Y$2,BD_LANÇAMENTOS!O:O,$A$4) -> 0 | D8: Maio | E8: =SUMIFS(BD_LANÇAMENTOS!D:D,BD_LANÇAMENTOS!M:M,D8,BD_LANÇAMENTOS!O:O,$A$4) -> 0
A9: REGINALDO | B9: =SUMIFS(BD_LANÇAMENTOS!D:D,BD_LANÇAMENTOS!C:C,A9,BD_LANÇAMENTOS!N:N,PROJETO!$Y$2,BD_LANÇAMENTOS!O:O,$A$4) -> 0 | D9: Junho | E9: =SUMIFS(BD_LANÇAMENTOS!D:D,BD_LANÇAMENTOS!M:M,D9,BD_LANÇAMENTOS!O:O,$A$4) -> 0
A10: AGNALDO | B10: =SUMIFS(BD_LANÇAMENTOS!D:D,BD_LANÇAMENTOS!C:C,A10,BD_LANÇAMENTOS!N:N,PROJETO!$Y$2,BD_LANÇAMENTOS!O:O,$A$4) -> 0 | D10: Julho | E10: =SUMIFS(BD_LANÇAMENTOS!D:D,BD_LANÇAMENTOS!M:M,D10,BD_LANÇAMENTOS!O:O,$A$4) -> 0
D11: Agosto | E11: =SUMIFS(BD_LANÇAMENTOS!D:D,BD_LANÇAMENTOS!M:M,D11,BD_LANÇAMENTOS!O:O,$A$4) -> 0
D12: Setembro | E12: =SUMIFS(BD_LANÇAMENTOS!D:D,BD_LANÇAMENTOS!M:M,D12,BD_LANÇAMENTOS!O:O,$A$4) -> 0
D13: Outubro | E13: =SUMIFS(BD_LANÇAMENTOS!D:D,BD_LANÇAMENTOS!M:M,D13,BD_LANÇAMENTOS!O:O,$A$4) -> 0
D14: Novembro | E14: =SUMIFS(BD_LANÇAMENTOS!D:D,BD_LANÇAMENTOS!M:M,D14,BD_LANÇAMENTOS!O:O,$A$4) -> 0
D15: Dezembro | E15: =SUMIFS(BD_LANÇAMENTOS!D:D,BD_LANÇAMENTOS!M:M,D15,BD_LANÇAMENTOS!O:O,$A$4) -> 0
E21: PRODUÇÃO
A22: CNC | B22: PRODUCAO | D22: Janeiro | E22: =SUMIFS(BD_LANÇAMENTOS!D:D,BD_LANÇAMENTOS!M:M,D22,BD_LANÇAMENTOS!O:O,$A$22) -> 0
A23: PATRICIA | B23: =SUMIFS(BD_LANÇAMENTOS!D:D,BD_LANÇAMENTOS!C:C,A23,BD_LANÇAMENTOS!N:N,PROJETO!$Y$2,BD_LANÇAMENTOS!O:O,$A$22) -> 0 | D23: Fevereiro | E23: =SUMIFS(BD_LANÇAMENTOS!D:D,BD_LANÇAMENTOS!M:M,D23,BD_LANÇAMENTOS!O:O,$A$22) -> 0
A24: DHIEGO | B24: =SUMIFS(BD_LANÇAMENTOS!D:D,BD_LANÇAMENTOS!C:C,A24,BD_LANÇAMENTOS!N:N,PROJETO!$Y$2,BD_LANÇAMENTOS!O:O,$A$22) -> 0 | D24: Março | E24: =SUMIFS(BD_LANÇAMENTOS!D:D,BD_LANÇAMENTOS!M:M,D24,BD_LANÇAMENTOS!O:O,$A$22) -> 0
A25: RAFAEL | B25: =SUMIFS(BD_LANÇAMENTOS!D:D,BD_LANÇAMENTOS!C:C,A25,BD_LANÇAMENTOS!N:N,PROJETO!$Y$2,BD_LANÇAMENTOS!O:O,$A$22) -> 0 | D25: Abril | E25: =SUMIFS(BD_LANÇAMENTOS!D:D,BD_LANÇAMENTOS!M:M,D25,BD_LANÇAMENTOS!O:O,$A$22) -> 0
A26: ALEXANDRO | B26: =SUMIFS(BD_LANÇAMENTOS!D:D,BD_LANÇAMENTOS!C:C,A26,BD_LANÇAMENTOS!N:N,PROJETO!$Y$2,BD_LANÇAMENTOS!O:O,$A$22) -> 0 | D26: Maio | E26: =SUMIFS(BD_LANÇAMENTOS!D:D,BD_LANÇAMENTOS!M:M,D26,BD_LANÇAMENTOS!O:O,$A$22) -> 0
A27: JOÃO EDUARDO | B27: =SUMIFS(BD_LANÇAMENTOS!D:D,BD_LANÇAMENTOS!C:C,A27,BD_LANÇAMENTOS!N:N,PROJETO!$Y$2,BD_LANÇAMENTOS!O:O,$A$22) -> 0 | D27: Junho | E27: =SUMIFS(BD_LANÇAMENTOS!D:D,BD_LANÇAMENTOS!M:M,D27,BD_LANÇAMENTOS!O:O,$A$22) -> 0
A28: TIAGO | B28: =SUMIFS(BD_LANÇAMENTOS!D:D,BD_LANÇAMENTOS!C:C,A28,BD_LANÇAMENTOS!N:N,PROJETO!$Y$2,BD_LANÇAMENTOS!O:O,$A$22) -> 0 | D28: Julho | E28: =SUMIFS(BD_LANÇAMENTOS!D:D,BD_LANÇAMENTOS!M:M,D28,BD_LANÇAMENTOS!O:O,$A$22) -> 0
D29: Agosto | E29: =SUMIFS(BD_LANÇAMENTOS!D:D,BD_LANÇAMENTOS!M:M,D29,BD_LANÇAMENTOS!O:O,$A$22) -> 0
D30: Setembro | E30: =SUMIFS(BD_LANÇAMENTOS!D:D,BD_LANÇAMENTOS!M:M,D30,BD_LANÇAMENTOS!O:O,$A$22) -> 0
D31: Outubro | E31: =SUMIFS(BD_LANÇAMENTOS!D:D,BD_LANÇAMENTOS!M:M,D31,BD_LANÇAMENTOS!O:O,$A$22) -> 0
D32: Novembro | E32: =SUMIFS(BD_LANÇAMENTOS!D:D,BD_LANÇAMENTOS!M:M,D32,BD_LANÇAMENTOS!O:O,$A$22) -> 0
D33: Dezembro | E33: =SUMIFS(BD_LANÇAMENTOS!D:D,BD_LANÇAMENTOS!M:M,D33,BD_LANÇAMENTOS!O:O,$A$22) -> 0
A35: SOLDA | B35: PRODUCAO | E35: PRODUÇÃO
A36: VINICIUS | B36: =SUMIFS(BD_LANÇAMENTOS!D:D,BD_LANÇAMENTOS!C:C,A36,BD_LANÇAMENTOS!N:N,PROJETO!$Y$2,BD_LANÇAMENTOS!O:O,$A$35) -> 0 | D36: Janeiro | E36: =SUMIFS(BD_LANÇAMENTOS!D:D,BD_LANÇAMENTOS!M:M,D36,BD_LANÇAMENTOS!O:O,$A$35) -> 0
A37: CLAUDINEI | B37: =SUMIFS(BD_LANÇAMENTOS!D:D,BD_LANÇAMENTOS!C:C,A37,BD_LANÇAMENTOS!N:N,PROJETO!$Y$2,BD_LANÇAMENTOS!O:O,$A$35) -> 0 | D37: Fevereiro | E37: =SUMIFS(BD_LANÇAMENTOS!D:D,BD_LANÇAMENTOS!M:M,D37,BD_LANÇAMENTOS!O:O,$A$35) -> 0
A38: EDMAR | B38: =SUMIFS(BD_LANÇAMENTOS!D:D,BD_LANÇAMENTOS!C:C,A38,BD_LANÇAMENTOS!N:N,PROJETO!$Y$2,BD_LANÇAMENTOS!O:O,$A$35) -> 0 | D38: Março | E38: =SUMIFS(BD_LANÇAMENTOS!D:D,BD_LANÇAMENTOS!M:M,D38,BD_LANÇAMENTOS!O:O,$A$35) -> 0
D39: Abril | E39: =SUMIFS(BD_LANÇAMENTOS!D:D,BD_LANÇAMENTOS!M:M,D39,BD_LANÇAMENTOS!O:O,$A$35) -> 0
D40: Maio | E40: =SUMIFS(BD_LANÇAMENTOS!D:D,BD_LANÇAMENTOS!M:M,D40,BD_LANÇAMENTOS!O:O,$A$35) -> 0
D41: Junho | E41: =SUMIFS(BD_LANÇAMENTOS!D:D,BD_LANÇAMENTOS!M:M,D41,BD_LANÇAMENTOS!O:O,$A$35) -> 0
D42: Julho | E42: =SUMIFS(BD_LANÇAMENTOS!D:D,BD_LANÇAMENTOS!M:M,D42,BD_LANÇAMENTOS!O:O,$A$35) -> 0
D43: Agosto | E43: =SUMIFS(BD_LANÇAMENTOS!D:D,BD_LANÇAMENTOS!M:M,D43,BD_LANÇAMENTOS!O:O,$A$35) -> 0
D44: Setembro | E44: =SUMIFS(BD_LANÇAMENTOS!D:D,BD_LANÇAMENTOS!M:M,D44,BD_LANÇAMENTOS!O:O,$A$35) -> 0
D45: Outubro | E45: =SUMIFS(BD_LANÇAMENTOS!D:D,BD_LANÇAMENTOS!M:M,D45,BD_LANÇAMENTOS!O:O,$A$35) -> 0
D46: Novembro | E46: =SUMIFS(BD_LANÇAMENTOS!D:D,BD_LANÇAMENTOS!M:M,D46,BD_LANÇAMENTOS!O:O,$A$35) -> 0
D47: Dezembro | E47: =SUMIFS(BD_LANÇAMENTOS!D:D,BD_LANÇAMENTOS!M:M,D47,BD_LANÇAMENTOS!O:O,$A$35) -> 0
